Exception in thread receiver:
Traceback (most recent call last):
  File "/home/le.chen/.conda/envs/westpa-2022.02/lib/python3.10/threading.py", line 1016, in _bootstrap_inner
